<?xml version="1.0"?>
<sdf version="1.6">
  <world name="ring_world">

    <plugin filename="gz-sim-physics-system"
            name="gz::sim::systems::Physics"/>
    <plugin filename="gz-sim-user-commands-system"
            name="gz::sim::systems::UserCommands"/>
    <plugin filename="gz-sim-scene-broadcaster-system"
            name="gz::sim::systems::SceneBroadcaster"/>
    <plugin filename="gz-sim-sensors-system"
            name="gz::sim::systems::Sensors"/>
    <plugin filename="gz-sim-imu-system"
            name="gz::sim::systems::Imu"/>
    <plugin
      filename="gz-sim-user-commands-system"
      name="gz::sim::systems::UserCommands">
    </plugin>

    <physics name="default_physics" type="ode">
      <real_time_update_rate>1000.0</real_time_update_rate>
      <max_step_size>0.001</max_step_size>
      <real_time_factor>1.0</real_time_factor>
    </physics>

    <light name="sun" type="directional">
      <cast_shadows>true</cast_shadows>
      <pose>0 0 10 0 0 0</pose>
      <diffuse>0.8 0.8 0.8 1</diffuse>
      <specular>0.2 0.2 0.2 1</specular>
      <attenuation>
        <range>1000</range>
        <constant>0.9</constant>
        <linear>0.01</linear>
        <quadratic>0.001</quadratic>
      </attenuation>
      <direction>-0.5 0.1 -0.9</direction>
    </light>

    <model name="ground_plane">
      <static>true</static>
      <link name="link">
        <collision name="collision">
          <geometry>
            <plane>
              <normal>0 0 1</normal>
              <size>100 100</size>
            </plane>
          </geometry>
        </collision>
        <visual name="visual">
          <geometry>
            <plane>
              <normal>0 0 1</normal>
              <size>100 100</size>
            </plane>
          </geometry>
          <material>
            <ambient>0.8 0.8 0.8 1</ambient>
            <diffuse>0.8 0.8 0.8 1</diffuse>
            <specular>0.8 0.8 0.8 1</specular>
          </material>
        </visual>
      </link>
    </model>

    <model name="wall_front">
      <static>true</static>
      <pose>2.5 0 0.5 0 0 0</pose>
      <link name="link">
        <collision name="collision">
          <geometry><box><size>0.2 5 1</size></box></geometry>
        </collision>
        <visual name="visual">
          <geometry><box><size>0.2 5 1</size></box></geometry>
          <material>
            <ambient>0.7 0.7 0.7 1</ambient>
            <diffuse>0.7 0.7 0.7 1</diffuse>
          </material>
        </visual>
      </link>
    </model>

    <model name="wall_back_red">
      <static>true</static>
      <pose>-2.5 0 0.5 0 0 0</pose>
      <link name="link">
        <collision name="collision">
          <geometry><box><size>0.2 5 1</size></box></geometry>
        </collision>
        <visual name="visual">
          <geometry><box><size>0.2 5 1</size></box></geometry>
          <material>
            <ambient>1 0 0 1</ambient>
            <diffuse>1 0 0 1</diffuse>
            <specular>0.5 0 0 1</specular>
          </material>
        </visual>
      </link>
    </model>

    <model name="wall_left">
      <static>true</static>
      <pose>0 2.5 0.5 0 0 1.5708</pose>
      <link name="link">
        <collision name="collision">
          <geometry><box><size>0.2 5 1</size></box></geometry>
        </collision>
        <visual name="visual">
          <geometry><box><size>0.2 5 1</size></box></geometry>
          <material>
            <ambient>0.7 0.7 0.7 1</ambient>
            <diffuse>0.7 0.7 0.7 1</diffuse>
          </material>
        </visual>
      </link>
    </model>

    <model name="wall_right">
      <static>true</static>
      <pose>0 -2.5 0.5 0 0 1.5708</pose>
      <link name="link">
        <collision name="collision">
          <geometry><box><size>0.2 5 1</size></box></geometry>
        </collision>
        <visual name="visual">
          <geometry><box><size>0.2 5 1</size></box></geometry>
          <material>
            <ambient>0.7 0.7 0.7 1</ambient>
            <diffuse>0.7 0.7 0.7 1</diffuse>
          </material>
        </visual>
      </link>
    </model>
    <model name="plate">
      <pose>-2 0 0 0 0 0</pose>
      <link name="link1">
        <inertial>
          <mass>10.0</mass>
          <inertia>
            <ixx>1.0</ixx>
            <iyy>1.0</iyy>
            <izz>1.0</izz>
            <ixy>0.0</ixy>
            <ixz>0.0</ixz>
            <iyz>0.0</iyz>
          </inertia>
        </inertial>
        <collision name="collision">
          <geometry><box><size>1 1 0.02</size></box></geometry>
        </collision>
        <visual name="visual">
          <geometry><box><size>1 1 0.02</size></box></geometry>
          <material>
            <ambient>1 1 0 1</ambient>
            <diffuse>1 1 0 1</diffuse>
          </material>
        </visual>
      </link>
      <link name="link2">
        <inertial>
          <mass>10.0</mass>
          <inertia>
            <ixx>1.0</ixx>
            <iyy>1.0</iyy>
            <izz>1.0</izz>
            <ixy>0.0</ixy>
            <ixz>0.0</ixz>
            <iyz>0.0</iyz>
          </inertia>
        </inertial>
        <collision name="collision">
          <geometry><box><size>1 1 0.02</size></box></geometry>
        </collision>
        <visual name="visual">
          <geometry><box><size>1 1 0.02</size></box></geometry>
          <material>
            <ambient>1 1 0 1</ambient>
            <diffuse>1 1 0 1</diffuse>
          </material>
        </visual>
      </link>
      <joint name="plate_joint" type="prismatic">
        <pose>0 0 0.5 0 0 0</pose>
        <parent>link1</parent>
        <child>link2</child>
        <axis>
          <xyz>0 0 1</xyz>
          <limit>
            <lower>-1</lower>
            <upper>1</upper>
            <effort>1e6</effort> 
          </limit>
        </axis>
      </joint>
      <plugin filename="gz-sim-joint-controller-system" name="gz::sim::systems::JointController">
        <joint_name>plate_joint</joint_name>
        <initial_velocity>1.0</initial_velocity>
      </plugin>
    </model>
  </world>
</sdf>